<mujoco model="go2">
    <compiler angle="radian" autolimits="true"/>

    <option cone="elliptic" impratio="100"/>
    <option timestep="0.002"/>

    <default>
        <default class="go2">
            <geom friction="0.6" margin="0.001" condim="1"/>
            <joint axis="0 1 0" damping="0.6" armature="0.01" frictionloss="0.2"/>
            <motor ctrlrange="-23.7 23.7"/>
            <default class="abduction">
                <joint axis="1 0 0" range="-1.0472 1.0472"/>
            </default>
            <default class="shoulder">
                <default class="front_shoulder">
                    <joint range="-1.5708 3.4907"/>
                </default>
                <default class="back_shoulder">
                    <joint range="-0.5236 4.5379"/>
                </default>
            </default>
            <default class="knee">
                <joint range="-2.7227 -0.83776"/>
                <motor ctrlrange="-45.43 45.43"/>
            </default>
            <default class="visual">
                <geom type="mesh" contype="0" conaffinity="0" group="2"/>
            </default>
            <default class="collision">
                <geom group="3"/>
                <default class="foot">
                    <geom size="0.022" pos="-0.002 0 -0.213" priority="1" solimp="0.015 1 0.031" condim="6"
                          friction="0.8 0.02 0.01"/>
                </default>
            </default>
        </default>
    </default>

    <asset>
        <material name="metal" rgba=".9 .95 .95 1"/>
        <material name="black" rgba="0 0 0 1"/>
        <material name="white" rgba="1 1 1 1"/>
        <material name="gray" rgba="0.671705 0.692426 0.774270 1"/>

        <mesh file="assets/base_0.obj"/>
        <mesh file="assets/base_1.obj"/>
        <mesh file="assets/base_2.obj"/>
        <mesh file="assets/base_3.obj"/>
        <mesh file="assets/base_4.obj"/>
        <mesh file="assets/hip_0.obj"/>
        <mesh file="assets/hip_1.obj"/>
        <mesh file="assets/thigh_0.obj"/>
        <mesh file="assets/thigh_1.obj"/>
        <mesh file="assets/thigh_mirror_0.obj"/>
        <mesh file="assets/thigh_mirror_1.obj"/>
        <mesh file="assets/calf_0.obj"/>
        <mesh file="assets/calf_1.obj"/>
        <mesh file="assets/calf_mirror_0.obj"/>
        <mesh file="assets/calf_mirror_1.obj"/>
        <mesh file="assets/foot.obj"/>
    </asset>

    <worldbody>
        <body name="base_link" pos="0 0 0.445" childclass="go2">
            <inertial pos="0.021112 0 -0.005366" quat="-0.000543471 0.713435 -0.00173769 0.700719" mass="6.921"
                      diaginertia="0.107027 0.0980771 0.0244531"/>
            <freejoint/>
            <geom mesh="base_0" material="black" class="visual"/>
            <geom mesh="base_1" material="black" class="visual"/>
            <geom mesh="base_2" material="black" class="visual"/>
            <geom mesh="base_3" material="white" class="visual"/>
            <geom mesh="base_4" material="gray" class="visual"/>
            <geom size="0.1881 0.04675 0.057" type="box" class="collision"/>
            <geom size="0.05 0.045" pos="0.285 0 0.01" type="cylinder" class="collision"/>
            <geom size="0.047" pos="0.293 0 -0.06" class="collision"/>
            <site name="imu" pos="-0.02557 0 0.04232"/>
            <body name="FL_shoulder" pos="0.1934 0.0465 0">
                <inertial pos="-0.0054 0.00194 -0.000105" quat="0.497014 0.499245 0.505462 0.498237" mass="0.678"
                          diaginertia="0.00088403 0.000596003 0.000479967"/>
                <joint name="FL_shoulder_joint" class="abduction"/>
                <geom mesh="hip_0" material="metal" class="visual"/>
                <geom mesh="hip_1" material="gray" class="visual"/>
                <geom size="0.046 0.02" pos="0 0.08 0" quat="1 1 0 0" type="cylinder" class="collision"/>
                <body name="FL_thigh" pos="0 0.0955 0">
                    <inertial pos="-0.00374 -0.0223 -0.0327" quat="0.829533 0.0847635 -0.0200632 0.551623" mass="1.152"
                              diaginertia="0.00594973 0.00584149 0.000878787"/>
                    <joint name="FL_thigh_joint" class="front_shoulder"/>
                    <geom mesh="thigh_0" material="metal" class="visual"/>
                    <geom mesh="thigh_1" material="gray" class="visual"/>
                    <geom size="0.1065 0.01225 0.017" pos="0 0 -0.1065" quat="0.707107 0 0.707107 0" type="box"
                          class="collision"/>
                    <body name="FL_calf" pos="0 0 -0.213">
                        <inertial pos="0.00629595 -0.000622121 -0.141417"
                                  quat="0.710672 0.00154099 -0.00450087 0.703508"
                                  mass="0.241352" diaginertia="0.0014901 0.00146356 5.31397e-05"/>
                        <joint name="FL_calf_joint" class="knee"/>
                        <geom mesh="calf_0" material="gray" class="visual"/>
                        <geom mesh="calf_1" material="black" class="visual"/>
                        <geom size="0.012 0.06" pos="0.008 0 -0.06" quat="0.994493 0 -0.104807 0" type="cylinder"
                              class="collision"/>
                        <geom size="0.011 0.0325" pos="0.02 0 -0.148" quat="0.999688 0 0.0249974 0" type="cylinder"
                              class="collision"/>
                        <geom pos="0 0 -0.213" mesh="foot" class="visual" material="black"/>
                        <geom name="FL_foot_collision" class="foot"/>
                    </body>
                </body>
            </body>
            <body name="FR_shoulder" pos="0.1934 -0.0465 0">
                <inertial pos="-0.0054 -0.00194 -0.000105" quat="0.498237 0.505462 0.499245 0.497014" mass="0.678"
                          diaginertia="0.00088403 0.000596003 0.000479967"/>
                <joint name="FR_shoulder_joint" class="abduction"/>
                <geom mesh="hip_0" material="metal" class="visual" quat="4.63268e-05 1 0 0"/>
                <geom mesh="hip_1" material="gray" class="visual" quat="4.63268e-05 1 0 0"/>
                <geom size="0.046 0.02" pos="0 -0.08 0" quat="0.707107 0.707107 0 0" type="cylinder" class="collision"/>
                <body name="FR_thigh" pos="0 -0.0955 0">
                    <inertial pos="-0.00374 0.0223 -0.0327" quat="0.551623 -0.0200632 0.0847635 0.829533" mass="1.152"
                              diaginertia="0.00594973 0.00584149 0.000878787"/>
                    <joint name="FR_thigh_joint" class="front_shoulder"/>
                    <geom mesh="thigh_mirror_0" material="metal" class="visual"/>
                    <geom mesh="thigh_mirror_1" material="gray" class="visual"/>
                    <geom size="0.1065 0.01225 0.017" pos="0 0 -0.1065" quat="0.707107 0 0.707107 0" type="box"
                          class="collision"/>
                    <body name="FR_calf" pos="0 0 -0.213">
                        <inertial pos="0.00629595 0.000622121 -0.141417" quat="0.703508 -0.00450087 0.00154099 0.710672"
                                  mass="0.241352" diaginertia="0.0014901 0.00146356 5.31397e-05"/>
                        <joint name="FR_calf_joint" class="knee"/>
                        <geom mesh="calf_mirror_0" material="gray" class="visual"/>
                        <geom mesh="calf_mirror_1" material="black" class="visual"/>
                        <geom size="0.013 0.06" pos="0.01 0 -0.06" quat="0.995004 0 -0.0998334 0" type="cylinder"
                              class="collision"/>
                        <geom size="0.011 0.0325" pos="0.02 0 -0.148" quat="0.999688 0 0.0249974 0" type="cylinder"
                              class="collision"/>
                        <geom pos="0 0 -0.213" mesh="foot" class="visual" material="black"/>
                        <geom name="FR_foot_collision" class="foot"/>
                    </body>
                </body>
            </body>
            <body name="BL_shoulder" pos="-0.1934 0.0465 0">
                <inertial pos="0.0054 0.00194 -0.000105" quat="0.505462 0.498237 0.497014 0.499245" mass="0.678"
                          diaginertia="0.00088403 0.000596003 0.000479967"/>
                <joint name="BL_shoulder_joint" class="abduction"/>
                <geom mesh="hip_0" material="metal" class="visual" quat="4.63268e-05 0 1 0"/>
                <geom mesh="hip_1" material="gray" class="visual" quat="4.63268e-05 0 1 0"/>
                <geom size="0.046 0.02" pos="0 0.08 0" quat="0.707107 0.707107 0 0" type="cylinder" class="collision"/>
                <body name="BL_thigh" pos="0 0.0955 0">
                    <inertial pos="-0.00374 -0.0223 -0.0327" quat="0.829533 0.0847635 -0.0200632 0.551623" mass="1.152"
                              diaginertia="0.00594973 0.00584149 0.000878787"/>
                    <joint name="BL_thigh_joint" class="back_shoulder"/>
                    <geom mesh="thigh_0" material="metal" class="visual"/>
                    <geom mesh="thigh_1" material="gray" class="visual"/>
                    <geom size="0.1065 0.01225 0.017" pos="0 0 -0.1065" quat="0.707107 0 0.707107 0" type="box"
                          class="collision"/>
                    <body name="BL_calf" pos="0 0 -0.213">
                        <inertial pos="0.00629595 -0.000622121 -0.141417"
                                  quat="0.710672 0.00154099 -0.00450087 0.703508"
                                  mass="0.241352" diaginertia="0.0014901 0.00146356 5.31397e-05"/>
                        <joint name="BL_calf_joint" class="knee"/>
                        <geom mesh="calf_0" material="gray" class="visual"/>
                        <geom mesh="calf_1" material="black" class="visual"/>
                        <geom size="0.013 0.06" pos="0.01 0 -0.06" quat="0.995004 0 -0.0998334 0" type="cylinder"
                              class="collision"/>
                        <geom size="0.011 0.0325" pos="0.02 0 -0.148" quat="0.999688 0 0.0249974 0" type="cylinder"
                              class="collision"/>
                        <geom pos="0 0 -0.213" mesh="foot" class="visual" material="black"/>
                        <geom name="BL_foot_collision" class="foot"/>
                    </body>
                </body>
            </body>
            <body name="BR_shoulder" pos="-0.1934 -0.0465 0">
                <inertial pos="0.0054 -0.00194 -0.000105" quat="0.499245 0.497014 0.498237 0.505462" mass="0.678"
                          diaginertia="0.00088403 0.000596003 0.000479967"/>
                <joint name="BR_shoulder_joint" class="abduction"/>
                <geom mesh="hip_0" material="metal" class="visual" quat="2.14617e-09 4.63268e-05 4.63268e-05 -1"/>
                <geom mesh="hip_1" material="gray" class="visual" quat="2.14617e-09 4.63268e-05 4.63268e-05 -1"/>
                <geom size="0.046 0.02" pos="0 -0.08 0" quat="0.707107 0.707107 0 0" type="cylinder" class="collision"/>
                <body name="BR_thigh" pos="0 -0.0955 0">
                    <inertial pos="-0.00374 0.0223 -0.0327" quat="0.551623 -0.0200632 0.0847635 0.829533" mass="1.152"
                              diaginertia="0.00594973 0.00584149 0.000878787"/>
                    <joint name="BR_thigh_joint" class="back_shoulder"/>
                    <geom mesh="thigh_mirror_0" material="metal" class="visual"/>
                    <geom mesh="thigh_mirror_1" material="gray" class="visual"/>
                    <geom size="0.1065 0.01225 0.017" pos="0 0 -0.1065" quat="0.707107 0 0.707107 0" type="box"
                          class="collision"/>
                    <body name="BR_calf" pos="0 0 -0.213">
                        <inertial pos="0.00629595 0.000622121 -0.141417" quat="0.703508 -0.00450087 0.00154099 0.710672"
                                  mass="0.241352" diaginertia="0.0014901 0.00146356 5.31397e-05"/>
                        <joint name="BR_calf_joint" class="knee"/>
                        <geom mesh="calf_mirror_0" material="gray" class="visual"/>
                        <geom mesh="calf_mirror_1" material="black" class="visual"/>
                        <geom size="0.013 0.06" pos="0.01 0 -0.06" quat="0.995004 0 -0.0998334 0" type="cylinder"
                              class="collision"/>
                        <geom size="0.011 0.0325" pos="0.02 0 -0.148" quat="0.999688 0 0.0249974 0" type="cylinder"
                              class="collision"/>
                        <geom pos="0 0 -0.213" mesh="foot" class="visual" material="black"/>
                        <geom name="BR_foot_collision" class="foot"/>
                    </body>
                </body>
            </body>
        </body>
    </worldbody>

    <actuator>
        <motor class="abduction" name="FL_shoulder_joint" joint="FL_shoulder_joint" ctrllimited="false"/>
        <motor class="shoulder" name="FL_thigh_joint" joint="FL_thigh_joint" ctrllimited="false"/>
        <motor class="knee" name="FL_calf_joint" joint="FL_calf_joint" ctrllimited="false"/>
        <motor class="abduction" name="FR_shoulder_joint" joint="FR_shoulder_joint" ctrllimited="false"/>
        <motor class="shoulder" name="FR_thigh_joint" joint="FR_thigh_joint" ctrllimited="false"/>
        <motor class="knee" name="FR_calf_joint" joint="FR_calf_joint" ctrllimited="false"/>
        <motor class="abduction" name="BL_shoulder_joint" joint="BL_shoulder_joint" ctrllimited="false"/>
        <motor class="shoulder" name="BL_thigh_joint" joint="BL_thigh_joint" ctrllimited="false"/>
        <motor class="knee" name="BL_calf_joint" joint="BL_calf_joint" ctrllimited="false"/>
        <motor class="abduction" name="BR_shoulder_joint" joint="BR_shoulder_joint" ctrllimited="false"/>
        <motor class="shoulder" name="BR_thigh_joint" joint="BR_thigh_joint" ctrllimited="false"/>
        <motor class="knee" name="BR_calf_joint" joint="BR_calf_joint" ctrllimited="false"/>
    </actuator>

    <keyframe>
        <key name="home" qpos="0 0 0.27 1 0 0 0 0 0.9 -1.8 0 0.9 -1.8 0 0.9 -1.8 0 0.9 -1.8"
             ctrl="0 0.9 -1.8 0 0.9 -1.8 0 0.9 -1.8 0 0.9 -1.8"/>
    </keyframe>
</mujoco>
